Workbook
Name CARI: 'Foto Produk'!$Q$4
Name harga1: 'Daftar Harga'!$L$4:$L$1000
Name logika: 'Daftar Harga'!$J$4:$K$13
Name NAMABARANG: 'Foto Produk'!$D$4:$D$63
Name PHOTO: 'Foto Produk'!$E$4:$E$63
Name photo10: 'Foto Produk'!$N$4:$N$63
Name photo11: 'Foto Produk'!$O$4:$O$63
Name photo2: 'Foto Produk'!$F$4:$F$63
Name photo3: 'Foto Produk'!$G$4:$G$63
Name photo4: 'Foto Produk'!$H$4:$H$63
Name photo5: 'Foto Produk'!$I$4:$I$63
Name photo6: 'Foto Produk'!$J$4:$J$63
Name photo7: 'Foto Produk'!$K$4:$K$63
Name photo8: 'Foto Produk'!$L$4:$L$63
Name photo9: 'Foto Produk'!$M$4:$M$63
Name TAMPIL: INDEX(PHOTO,MATCH(CARI,NAMABARANG,0))
Name tampil10: INDEX(photo10,MATCH(CARI,NAMABARANG,0))
Name tampil11: INDEX(photo11,MATCH(CARI,NAMABARANG,0))
Name tampil2: INDEX(photo2,MATCH(CARI,NAMABARANG,0))
Name tampil3: INDEX(photo3,MATCH(CARI,NAMABARANG,0))
Name tampil4: INDEX(photo4,MATCH(CARI,NAMABARANG,0))
Name tampil5: INDEX(photo5,MATCH(CARI,NAMABARANG,0))
Name tampil6: INDEX(photo6,MATCH(CARI,NAMABARANG,0))
Name tampil7: INDEX(photo7,MATCH(CARI,NAMABARANG,0))
Name tampil8: INDEX(photo8,MATCH(CARI,NAMABARANG,0))
Name tampil9: INDEX(photo9,MATCH(CARI,NAMABARANG,0))

Sheet Data Supply
B2: Data Barang dan Supplier
B3: Hari/Tanggal Order | C3: Hari/Tanggal Sampai | D3: Nama Bank | E3: Nama Rekening | F3: No Rekening | G3: Nama Supplier | H3: No | I3: Nama Barang | J3: Kode | K3: Banyak | L3: Satuan | M3: Harga Satuan | N3: Jumlah Order | O3: Biaya Kurir | P3: Jenis Kurir | Q3: Biaya Transfer | R3: Total Jumlah Order | S3: Total Jumlah Order | T3: Keterangan | U3: TOTAL MODAL
B4: 44627 | D4: BCA | E4: NUR ALHAMID | F4: 8670013261 | G4: Nur | H4: 1 | I4: Terusan Bordir | J4: =LEFT(G4,3)&H4 -> Nur1 | K4: 9 | L4: Pcs | M4: =N4/K4+$T$5 -> 147595.51 | N4: 1305000 | O4: 35000 | P4: Gojek Expedisi | Q4: 6000 | R4: =SUM(N4:O16)+SUM(Q4:Q16) -> 11351000 | S4: =SUM(R4:R16) -> 11351000 | T4: ="Jumlah Pcs "&SUM(K3:K16) -> Jumlah Pcs 89 | U4: =SUM(S4:S60) -> 50340000
B5: 44627 | D5: BCA | E5: NUR ALHAMID | F5: 8670013261 | G5: Nur | H5: 2 | I5: Bordir Alisha | J5: =LEFT(G5,3)&H5 -> Nur2 | K5: 3 | L5: Pcs | M5: =N5/K5+$T$5 -> 127595.51 | N5: 375000 | O5: 190000 | P5: Karyati | T5: =(O4+O5+Q4)/SUM(K4:K16) -> 2595.5056
B6: 44627 | D6: BCA | E6: NUR ALHAMID | F6: 8670013261 | G6: Nur | H6: 3 | I6: Terusan Motif | J6: =LEFT(G6,3)&H6 -> Nur3 | K6: 23 | L6: Pcs | M6: =N6/K6+$T$5 -> 117595.51 | N6: 2645000 | T6: Biaya Ongkir per pcs
B7: 44627 | D7: BCA | E7: NUR ALHAMID | F7: 8670013261 | G7: Nur | H7: 4 | I7: Ms Style | J7: =LEFT(G7,3)&H7 -> Nur4 | K7: 5 | L7: Pcs | M7: =N7/K7+$T$5 -> 122595.51 | N7: 600000
B8: 44627 | D8: BCA | E8: NUR ALHAMID | F8: 8670013261 | G8: Nur | H8: 5 | I8: Abb Motif | J8: =LEFT(G8,3)&H8 -> Nur5 | K8: 12 | L8: Pcs | M8: =N8/K8+$T$5 -> 148428.84 | N8: 1750000
B9: 44627 | D9: BCA | E9: NUR ALHAMID | F9: 8670013261 | G9: Nur | H9: 6 | I9: Abb Bordir | J9: =LEFT(G9,3)&H9 -> Nur6 | K9: 2 | L9: Pcs | M9: =N9/K9+$T$5 -> 167595.51 | N9: 330000
B10: 44627 | D10: BCA | E10: NUR ALHAMID | F10: 8670013261 | G10: Nur | H10: 7 | I10: Abb Bordir 261 | J10: =LEFT(G10,3)&H10 -> Nur7 | K10: 2 | L10: Pcs | M10: =N10/K10+$T$5 -> 177595.51 | N10: 350000
B11: 44627 | D11: BCA | E11: NUR ALHAMID | F11: 8670013261 | G11: Nur | H11: 8 | I11: Abh Motif | J11: =LEFT(G11,3)&H11 -> Nur8 | K11: 13 | L11: Pcs | M11: =N11/K11+$T$5 -> 132595.51 | N11: 1690000
B12: 44627 | D12: BCA | E12: NUR ALHAMID | F12: 8670013261 | G12: Nur | H12: 9 | I12: Anak XL | J12: =LEFT(G12,3)&H12 -> Nur9 | K12: 7 | L12: Pcs | M12: =N12/K12+$T$5 -> 112595.51 | N12: 770000
B13: 44627 | D13: BCA | E13: NUR ALHAMID | F13: 8670013261 | G13: Nur | H13: 10 | I13: Anak L | J13: =LEFT(G13,3)&H13 -> Nur10 | K13: 1 | L13: Pcs | M13: =N13/K13+$T$5 -> 97595.506 | N13: 95000
B14: 44627 | D14: BCA | E14: NUR ALHAMID | F14: 8670013261 | G14: Nur | H14: 11 | I14: Anak M | J14: =LEFT(G14,3)&H14 -> Nur11 | K14: 6 | L14: Pcs | M14: =N14/K14+$T$5 -> 87595.506 | N14: 510000
B15: 44627 | D15: BCA | E15: NUR ALHAMID | F15: 8670013261 | G15: Nur | H15: 12 | I15: Abh Anak M | J15: =LEFT(G15,3)&H15 -> Nur12 | K15: 2 | L15: Pcs | M15: =N15/K15+$T$5 -> 112595.51 | N15: 220000
B16: 44627 | D16: BCA | E16: NUR ALHAMID | F16: 8670013261 | G16: Nur | H16: 13 | I16: Abh Anak L | J16: =LEFT(G16,3)&H16 -> Nur13 | K16: 4 | L16: Pcs | M16: =N16/K16+$T$5 -> 122595.51 | N16: 480000
B17: 44630 | D17: BRI | G17: Mukena Alwiyah | H17: 14 | I17: Abh Motif | J17: =LEFT(G17,3)&H17 -> Muk14 | K17: 9 | L17: Pcs | M17: =N17/K17 -> 125000 | N17: 1125000 | R17: =SUM(N17:O19) -> 2595000 | S17: =SUM(Q17:R19) -> 2595000 | T17: ="Jumlah Pcs "&SUM(K17:K19) -> Jumlah Pcs 22
B18: 44630 | D18: BRI | G18: Mukena Alwiyah | H18: 15 | I18: Terusan Motif | J18: =LEFT(G18,3)&H18 -> Muk15 | K18: 3 | L18: Pcs | M18: =N18/K18 -> 115000 | N18: 345000
B19: 44630 | D19: BRI | G19: Mukena Alwiyah | H19: 16 | I19: Abh Terompah | J19: =LEFT(G19,3)&H19 -> Muk16 | K19: 10 | L19: Pcs | M19: =N19/K19 -> 112500 | N19: 1125000
B20: 44634 | D20: BRI | E20: PHANG FUI NEN | F20: 120301000178561 | G20: Asya Muslim Fashion | H20: 17 | I20: M006 | J20: =LEFT(G20,3)&H20 -> Asy17 | K20: 12 | L20: Pcs | M20: =N20/K20 -> 90000 | N20: 1080000 | Q20: 6000 | R20: =SUM(N20:O34)+Q20 -> 11396000 | S20: =SUM(R20:R52) -> 16906000 | T20: No Nota : M00254
B21: 44634 | D21: BRI | E21: PHANG FUI NEN | F21: 120301000178561 | G21: Asya Muslim Fashion | H21: 18 | I21: M005 | J21: =LEFT(G21,3)&H21 -> Asy18 | K21: 12 | L21: Pcs | M21: =N21/K21 -> 75000 | N21: 900000 | T21: ="Jumlah Pcs "&SUM(K20:K34) -> Jumlah Pcs 129
B22: 44634 | D22: BRI | E22: PHANG FUI NEN | F22: 120301000178561 | G22: Asya Muslim Fashion | H22: 19 | I22: M002 | J22: =LEFT(G22,3)&H22 -> Asy19 | K22: 24 | L22: Pcs | M22: =N22/K22 -> 80000 | N22: 1920000
B23: 44634 | D23: BRI | E23: PHANG FUI NEN | F23: 120301000178561 | G23: Asya Muslim Fashion | H23: 20 | I23: M001 | J23: =LEFT(G23,3)&H23 -> Asy20 | K23: 12 | L23: Pcs | M23: =N23/K23 -> 75000 | N23: 900000
B24: 44634 | D24: BRI | E24: PHANG FUI NEN | F24: 120301000178561 | G24: Asya Muslim Fashion | H24: 21 | I24: M007 | J24: =LEFT(G24,3)&H24 -> Asy21 | K24: 24 | L24: Pcs | M24: =N24/K24 -> 85000 | N24: 2040000
B25: 44634 | D25: BRI | E25: PHANG FUI NEN | F25: 120301000178561 | G25: Asya Muslim Fashion | H25: 22 | I25: M008 | J25: =LEFT(G25,3)&H25 -> Asy22 | K25: 12 | L25: Pcs | M25: =N25/K25 -> 80000 | N25: 960000
B26: 44634 | D26: BRI | E26: PHANG FUI NEN | F26: 120301000178561 | G26: Asya Muslim Fashion | H26: 23 | I26: M004 | J26: =LEFT(G26,3)&H26 -> Asy23 | K26: 12 | L26: Pcs | M26: =N26/K26 -> 90000 | N26: 1080000
B27: 44634 | D27: BRI | E27: PHANG FUI NEN | F27: 120301000178561 | G27: Asya Muslim Fashion | H27: 24 | I27: SL324 | J27: =LEFT(G27,3)&H27 -> Asy24 | K27: 1 | L27: Pcs | M27: =N27/K27 -> 160000 | N27: 160000
B28: 44634 | D28: BRI | E28: PHANG FUI NEN | F28: 120301000178561 | G28: Asya Muslim Fashion | H28: 25 | I28: 9836 | J28: =LEFT(G28,3)&H28 -> Asy25 | K28: 1 | L28: Pcs | M28: =N28/K28 -> 135000 | N28: 135000
B29: 44634 | D29: BRI | E29: PHANG FUI NEN | F29: 120301000178561 | G29: Asya Muslim Fashion | H29: 26 | I29: 9607 | J29: =LEFT(G29,3)&H29 -> Asy26 | K29: 3 | L29: Pcs | M29: =N29/K29 -> 125000 | N29: 375000
B30: 44634 | D30: BRI | E30: PHANG FUI NEN | F30: 120301000178561 | G30: Asya Muslim Fashion | H30: 27 | I30: JMBO | J30: =LEFT(G30,3)&H30 -> Asy27 | K30: 4 | L30: Pcs | M30: =N30/K30 -> 170000 | N30: 680000
B31: 44634 | D31: BRI | E31: PHANG FUI NEN | F31: 120301000178561 | G31: Asya Muslim Fashion | H31: 28 | I31: 10663 | J31: =LEFT(G31,3)&H31 -> Asy28 | K31: 2 | L31: Pcs | M31: =N31/K31 -> 100000 | N31: 200000
B32: 44634 | D32: BRI | E32: PHANG FUI NEN | F32: 120301000178561 | G32: Asya Muslim Fashion | H32: 29 | I32: 10650 | J32: =LEFT(G32,3)&H32 -> Asy29 | K32: 4 | L32: Pcs | M32: =N32/K32 -> 95000 | N32: 380000
B33: 44634 | D33: BRI | E33: PHANG FUI NEN | F33: 120301000178561 | G33: Asya Muslim Fashion | H33: 30 | I33: 10680 | J33: =LEFT(G33,3)&H33 -> Asy30 | K33: 2 | L33: Pcs | M33: =N33/K33 -> 100000 | N33: 200000
B34: 44634 | D34: BRI | E34: PHANG FUI NEN | F34: 120301000178561 | G34: Asya Muslim Fashion | H34: 31 | I34: 10580 | J34: =LEFT(G34,3)&H34 -> Asy31 | K34: 4 | L34: Pcs | M34: =N34/K34 -> 95000 | N34: 380000
B35: 44634 | D35: BRI | E35: PHANG FUI NEN | F35: 120301000178561 | G35: Asya Muslim Fashion | H35: 32 | I35: 10567 | J35: =LEFT(G35,3)&H35 -> Asy32 | K35: 1 | L35: Pcs | M35: =N35/K35 -> 100000 | N35: 100000 | R35: =SUM(N35:O47) -> 3950000 | T35: No Nota : M00256
B36: 44634 | D36: BRI | E36: PHANG FUI NEN | F36: 120301000178561 | G36: Asya Muslim Fashion | H36: 33 | I36: 10466 | J36: =LEFT(G36,3)&H36 -> Asy33 | K36: 3 | L36: Pcs | M36: =N36/K36 -> 140000 | N36: 420000 | T36: ="Jumlah Pcs "&SUM(K35:K49) -> Jumlah Pcs 36
B37: 44634 | D37: BRI | E37: PHANG FUI NEN | F37: 120301000178561 | G37: Asya Muslim Fashion | H37: 34 | I37: 9855 | J37: =LEFT(G37,3)&H37 -> Asy34 | K37: 1 | L37: Pcs | M37: =N37/K37 -> 95000 | N37: 95000
B38: 44634 | D38: BRI | E38: PHANG FUI NEN | F38: 120301000178561 | G38: Asya Muslim Fashion | H38: 35 | I38: 10817 | J38: =LEFT(G38,3)&H38 -> Asy35 | K38: 3 | L38: Pcs | M38: =N38/K38 -> 95000 | N38: 285000
B39: 44634 | D39: BRI | E39: PHANG FUI NEN | F39: 120301000178561 | G39: Asya Muslim Fashion | H39: 36 | I39: 10737 | J39: =LEFT(G39,3)&H39 -> Asy36 | K39: 3 | L39: Pcs | M39: =N39/K39 -> 113333.33 | N39: 340000
B40: 44634 | D40: BRI | E40: PHANG FUI NEN | F40: 120301000178561 | G40: Asya Muslim Fashion | H40: 37 | I40: 8274 | J40: =LEFT(G40,3)&H40 -> Asy37 | K40: 2 | L40: Pcs | M40: =N40/K40 -> 100000 | N40: 200000
B41: 44634 | D41: BRI | E41: PHANG FUI NEN | F41: 120301000178561 | G41: Asya Muslim Fashion | H41: 38 | I41: 10403 | J41: =LEFT(G41,3)&H41 -> Asy38 | K41: 3 | L41: Pcs | M41: =N41/K41 -> 105000 | N41: 315000
...

Sheet Foto Produk
B2: Daftar Barang
B3: Kode | C3: No | D3: Nama Barang | E3: Keterangan | F3: Foto 1 | G3: Foto 2 | H3: Foto 3 | I3: Foto 4 | J3: Foto 5 | K3: Foto 6 | L3: Foto 7 | M3: Foto 8 | N3: Foto 9 | O3: Foto 10 | Q3: CARI | R3: Keterangan | S3: Foto 1 | T3: Foto 2 | U3: Foto 3 | V3: Foto 4 | W3: Foto 5 | X3: Foto 6 | Y3: Foto 7 | Z3: Foto 8 | AA3: Foto 9 | AB3: Foto 10
B4: =VLOOKUP(D4,'Data Supply'!$I$4:$J$63,2,0) -> Nur1 | C4: 1 | D4: =VLOOKUP(C4,'Data Supply'!$H$4:$I$63,2,0) -> Terusan Bordir | Q4: terusan bordir
B5: =VLOOKUP(D5,'Data Supply'!$I$4:$J$63,2,0) -> Nur2 | C5: 2 | D5: =VLOOKUP(C5,'Data Supply'!$H$4:$I$63,2,0) -> Bordir Alisha
B6: =VLOOKUP(D6,'Data Supply'!$I$4:$J$63,2,0) -> Nur3 | C6: 3 | D6: =VLOOKUP(C6,'Data Supply'!$H$4:$I$63,2,0) -> Terusan Motif
B7: =VLOOKUP(D7,'Data Supply'!$I$4:$J$63,2,0) -> Nur4 | C7: 4 | D7: =VLOOKUP(C7,'Data Supply'!$H$4:$I$63,2,0) -> Ms Style
B8: =VLOOKUP(D8,'Data Supply'!$I$4:$J$63,2,0) -> Nur5 | C8: 5 | D8: =VLOOKUP(C8,'Data Supply'!$H$4:$I$63,2,0) -> Abb Motif
B9: =VLOOKUP(D9,'Data Supply'!$I$4:$J$63,2,0) -> Nur6 | C9: 6 | D9: =VLOOKUP(C9,'Data Supply'!$H$4:$I$63,2,0) -> Abb Bordir
B10: =VLOOKUP(D10,'Data Supply'!$I$4:$J$63,2,0) -> Nur7 | C10: 7 | D10: =VLOOKUP(C10,'Data Supply'!$H$4:$I$63,2,0) -> Abb Bordir 261
B11: =VLOOKUP(D11,'Data Supply'!$I$4:$J$63,2,0) -> Nur8 | C11: 8 | D11: =VLOOKUP(C11,'Data Supply'!$H$4:$I$63,2,0) -> Abh Motif
B12: =VLOOKUP(D12,'Data Supply'!$I$4:$J$63,2,0) -> Nur9 | C12: 9 | D12: =VLOOKUP(C12,'Data Supply'!$H$4:$I$63,2,0) -> Anak XL
B13: =VLOOKUP(D13,'Data Supply'!$I$4:$J$63,2,0) -> Nur10 | C13: 10 | D13: =VLOOKUP(C13,'Data Supply'!$H$4:$I$63,2,0) -> Anak L
B14: =VLOOKUP(D14,'Data Supply'!$I$4:$J$63,2,0) -> Nur11 | C14: 11 | D14: =VLOOKUP(C14,'Data Supply'!$H$4:$I$63,2,0) -> Anak M
B15: =VLOOKUP(D15,'Data Supply'!$I$4:$J$63,2,0) -> Nur12 | C15: 12 | D15: =VLOOKUP(C15,'Data Supply'!$H$4:$I$63,2,0) -> Abh Anak M
B16: =VLOOKUP(D16,'Data Supply'!$I$4:$J$63,2,0) -> Nur13 | C16: 13 | D16: =VLOOKUP(C16,'Data Supply'!$H$4:$I$63,2,0) -> Abh Anak L
... B63: =VLOOKUP(D63,'Data Supply'!$I$4:$J$63,2,0) -> #N/A | C63: 60 | D63: =VLOOKUP(C63,'Data Supply'!$H$4:$I$63,2,0) -> #N/A

Sheet Input Penjualan
B2: Inputan Penjualan | M2: Daftar Stok
B3: Hari, Tanggal Transaksi | C3: No | D3: Nama Barang | E3: Kode | F3: Jumlah | G3: Satuan | H3: Harga Jual | I3: Total | J3: Keterangan | M3: No | N3: Nama Barang | O3: Kode | P3: Penjualan | Q3: Sisa Stok
B4: =IF(D4="","",TODAY()) -> 44638 | C4: =IF(B4="","",ROW()-3) -> 1 | D4: 10466 | E4: =IFERROR(VLOOKUP(D4,'Data Supply'!$I$4:$J$60,2,0),"") -> Asy33 | F4: 1 | G4: =IF(F4="","","Pcs") -> Pcs | H4: 205000 | I4: =IF(H4*F4=0,"",H4*F4) -> 205000 | M4: ='Data Supply'!H4 -> 1 | N4: ='Data Supply'!I4 -> Terusan Bordir | O4: ='Data Supply'!J4 -> Nur1 | P4: =SUMIF($E$4:$E$60,O4,$F$4:$F$60) -> 0 | Q4: ='Data Supply'!$K$4:$K$60-P4 -> 9
B5: =IF(D5="","",TODAY()) -> 44638 | C5: =IF(B5="","",ROW()-3) -> 2 | D5: Bordir Alisha | E5: =IFERROR(VLOOKUP(D5,'Data Supply'!$I$4:$J$60,2,0),"") -> Nur2 | F5: 3 | G5: =IF(F5="","","Pcs") -> Pcs | H5: 190000 | I5: =IF(H5*F5=0,"",H5*F5) -> 570000 | M5: ='Data Supply'!H5 -> 2 | N5: ='Data Supply'!I5 -> Bordir Alisha | O5: ='Data Supply'!J5 -> Nur2 | P5: =SUMIF($E$4:$E$60,O5,$F$4:$F$60) -> 3 | Q5: ='Data Supply'!$K$4:$K$60-P5 -> 0
B6: =IF(D6="","",TODAY()) -> 44638 | C6: =IF(B6="","",ROW()-3) -> 3 | D6: Abb Motif | E6: =IFERROR(VLOOKUP(D6,'Data Supply'!$I$4:$J$60,2,0),"") -> Nur5 | G6: =IF(F6="","","Pcs") | I6: =IF(H6*F6=0,"",H6*F6) | M6: ='Data Supply'!H6 -> 3 | N6: ='Data Supply'!I6 -> Terusan Motif | O6: ='Data Supply'!J6 -> Nur3 | P6: =SUMIF($E$4:$E$60,O6,$F$4:$F$60) -> 0 | Q6: ='Data Supply'!$K$4:$K$60-P6 -> 23
B7: =IF(D7="","",TODAY()) | C7: =IF(B7="","",ROW()-3) | E7: =IFERROR(VLOOKUP(D7,'Data Supply'!$I$4:$J$60,2,0),"") | G7: =IF(F7="","","Pcs") | I7: =IF(H7*F7=0,"",H7*F7) | M7: ='Data Supply'!H7 -> 4 | N7: ='Data Supply'!I7 -> Ms Style | O7: ='Data Supply'!J7 -> Nur4 | P7: =SUMIF($E$4:$E$60,O7,$F$4:$F$60) -> 0 | Q7: ='Data Supply'!$K$4:$K$60-P7 -> 5
B8: =IF(D8="","",TODAY()) | C8: =IF(B8="","",ROW()-3) | E8: =IFERROR(VLOOKUP(D8,'Data Supply'!$I$4:$J$60,2,0),"") | G8: =IF(F8="","","Pcs") | I8: =IF(H8*F8=0,"",H8*F8) | M8: ='Data Supply'!H8 -> 5 | N8: ='Data Supply'!I8 -> Abb Motif | O8: ='Data Supply'!J8 -> Nur5 | P8: =SUMIF($E$4:$E$60,O8,$F$4:$F$60) -> 0 | Q8: ='Data Supply'!$K$4:$K$60-P8 -> 12
B9: =IF(D9="","",TODAY()) | C9: =IF(B9="","",ROW()-3) | E9: =IFERROR(VLOOKUP(D9,'Data Supply'!$I$4:$J$60,2,0),"") | G9: =IF(F9="","","Pcs") | I9: =IF(H9*F9=0,"",H9*F9) | M9: ='Data Supply'!H9 -> 6 | N9: ='Data Supply'!I9 -> Abb Bordir | O9: ='Data Supply'!J9 -> Nur6 | P9: =SUMIF($E$4:$E$60,O9,$F$4:$F$60) -> 0 | Q9: ='Data Supply'!$K$4:$K$60-P9 -> 2
B10: =IF(D10="","",TODAY()) | C10: =IF(B10="","",ROW()-3) | E10: =IFERROR(VLOOKUP(D10,'Data Supply'!$I$4:$J$60,2,0),"") | G10: =IF(F10="","","Pcs") | I10: =IF(H10*F10=0,"",H10*F10) | M10: ='Data Supply'!H10 -> 7 | N10: ='Data Supply'!I10 -> Abb Bordir 261 | O10: ='Data Supply'!J10 -> Nur7 | P10: =SUMIF($E$4:$E$60,O10,$F$4:$F$60) -> 0 | Q10: ='Data Supply'!$K$4:$K$60-P10 -> 2
B11: =IF(D11="","",TODAY()) | C11: =IF(B11="","",ROW()-3) | E11: =IFERROR(VLOOKUP(D11,'Data Supply'!$I$4:$J$60,2,0),"") | G11: =IF(F11="","","Pcs") | I11: =IF(H11*F11=0,"",H11*F11) | M11: ='Data Supply'!H11 -> 8 | N11: ='Data Supply'!I11 -> Abh Motif | O11: ='Data Supply'!J11 -> Nur8 | P11: =SUMIF($E$4:$E$60,O11,$F$4:$F$60) -> 0 | Q11: ='Data Supply'!$K$4:$K$60-P11 -> 13
B12: =IF(D12="","",TODAY()) | C12: =IF(B12="","",ROW()-3) | E12: =IFERROR(VLOOKUP(D12,'Data Supply'!$I$4:$J$60,2,0),"") | G12: =IF(F12="","","Pcs") | I12: =IF(H12*F12=0,"",H12*F12) | M12: ='Data Supply'!H12 -> 9 | N12: ='Data Supply'!I12 -> Anak XL | O12: ='Data Supply'!J12 -> Nur9 | P12: =SUMIF($E$4:$E$60,O12,$F$4:$F$60) -> 0 | Q12: ='Data Supply'!$K$4:$K$60-P12 -> 7
B13: =IF(D13="","",TODAY()) | C13: =IF(B13="","",ROW()-3) | E13: =IFERROR(VLOOKUP(D13,'Data Supply'!$I$4:$J$60,2,0),"") | G13: =IF(F13="","","Pcs") | I13: =IF(H13*F13=0,"",H13*F13) | M13: ='Data Supply'!H13 -> 10 | N13: ='Data Supply'!I13 -> Anak L | O13: ='Data Supply'!J13 -> Nur10 | P13: =SUMIF($E$4:$E$60,O13,$F$4:$F$60) -> 0 | Q13: ='Data Supply'!$K$4:$K$60-P13 -> 1
B14: =IF(D14="","",TODAY()) | C14: =IF(B14="","",ROW()-3) | E14: =IFERROR(VLOOKUP(D14,'Data Supply'!$I$4:$J$60,2,0),"") | G14: =IF(F14="","","Pcs") | I14: =IF(H14*F14=0,"",H14*F14) | M14: ='Data Supply'!H14 -> 11 | N14: ='Data Supply'!I14 -> Anak M | O14: ='Data Supply'!J14 -> Nur11 | P14: =SUMIF($E$4:$E$60,O14,$F$4:$F$60) -> 0 | Q14: ='Data Supply'!$K$4:$K$60-P14 -> 6
B15: =IF(D15="","",TODAY()) | C15: =IF(B15="","",ROW()-3) | E15: =IFERROR(VLOOKUP(D15,'Data Supply'!$I$4:$J$60,2,0),"") | G15: =IF(F15="","","Pcs") | I15: =IF(H15*F15=0,"",H15*F15) | M15: ='Data Supply'!H15 -> 12 | N15: ='Data Supply'!I15 -> Abh Anak M | O15: ='Data Supply'!J15 -> Nur12 | P15: =SUMIF($E$4:$E$60,O15,$F$4:$F$60) -> 0 | Q15: ='Data Supply'!$K$4:$K$60-P15 -> 2
B16: =IF(D16="","",TODAY()) | C16: =IF(B16="","",ROW()-3) | E16: =IFERROR(VLOOKUP(D16,'Data Supply'!$I$4:$J$60,2,0),"") | G16: =IF(F16="","","Pcs") | I16: =IF(H16*F16=0,"",H16*F16) | M16: ='Data Supply'!H16 -> 13 | N16: ='Data Supply'!I16 -> Abh Anak L | O16: ='Data Supply'!J16 -> Nur13 | P16: =SUMIF($E$4:$E$60,O16,$F$4:$F$60) -> 0 | Q16: ='Data Supply'!$K$4:$K$60-P16 -> 4
B17: =IF(D17="","",TODAY()) | C17: =IF(B17="","",ROW()-3) | E17: =IFERROR(VLOOKUP(D17,'Data Supply'!$I$4:$J$60,2,0),"") | G17: =IF(F17="","","Pcs") | I17: =IF(H17*F17=0,"",H17*F17) | M17: ='Data Supply'!H17 -> 14 | N17: ='Data Supply'!I17 -> Abh Motif | O17: ='Data Supply'!J17 -> Muk14 | P17: =SUMIF($E$4:$E$60,O17,$F$4:$F$60) -> 0 | Q17: ='Data Supply'!$K$4:$K$60-P17 -> 9
B18: =IF(D18="","",TODAY()) | C18: =IF(B18="","",ROW()-3) | E18: =IFERROR(VLOOKUP(D18,'Data Supply'!$I$4:$J$60,2,0),"") | G18: =IF(F18="","","Pcs") | I18: =IF(H18*F18=0,"",H18*F18) | M18: ='Data Supply'!H18 -> 15 | N18: ='Data Supply'!I18 -> Terusan Motif | O18: ='Data Supply'!J18 -> Muk15 | P18: =SUMIF($E$4:$E$60,O18,$F$4:$F$60) -> 0 | Q18: ='Data Supply'!$K$4:$K$60-P18 -> 3
... B50: =IF(D50="","",TODAY()) | C50: =IF(B50="","",ROW()-3) | E50: =IFERROR(VLOOKUP(D50,'Data Supply'!$I$4:$J$60,2,0),"") | G50: =IF(F50="","","Pcs") | I50: =IF(H50*F50=0,"",H50*F50) | M50: ='Data Supply'!H50 -> 47 | N50: ='Data Supply'!I50 -> 10586 | O50: ='Data Supply'!J50 -> Asy47 | P50: =SUMIF($E$4:$E$60,O50,$F$4:$F$60) -> 0 | Q50: ='Data Supply'!$K$4:$K$60-P50 -> 3

Sheet Daftar Harga
B2: Daftar Harga Jual | J2: Tabel Logika
B3: No | C3: Nama Barang | D3: Kode | E3: Minimal | F3: Standar | G3: Kode Harga Minimal | J3: Angka | K3: Huruf | L3: Harga 1 | M3: Digit 1 | N3: Digit 2 | O3: Digit 3 | P3: Kode 1 | Q3: Kode 2 | R3: Kode 3 | S3: Kode Harga
B4: ='Data Supply'!H4 -> 1 | C4: ='Data Supply'!I4 -> Terusan Bordir | D4: ='Data Supply'!J4 -> Nur1 | G4: =_xlfn.IFNA(VLOOKUP(E4,$L$4:$S$550,8,FALSE),"") | J4: 0 | K4: A | L4: 100000 | M4: =VALUE(LEFT(L4,1)) -> 1 | N4: =VALUE(MID(L4,2,1)) -> 0 | O4: =VALUE(MID(L4,3,1)) -> 0 | P4: =VLOOKUP(M4,logika,2,FALSE) -> B | Q4: =VLOOKUP(N4,logika,2,FALSE) -> A | R4: =VLOOKUP(O4,logika,2,FALSE) -> A | S4: =CONCATENATE(P4,Q4,R4) -> BAA
B5: ='Data Supply'!H5 -> 2 | C5: ='Data Supply'!I5 -> Bordir Alisha | D5: ='Data Supply'!J5 -> Nur2 | G5: =_xlfn.IFNA(VLOOKUP(E5,$L$4:$S$550,8,FALSE),"") | J5: 1 | K5: B | L5: =L4+1000 -> 101000 | M5: =VALUE(LEFT(L5,1)) -> 1 | N5: =VALUE(MID(L5,2,1)) -> 0 | O5: =VALUE(MID(L5,3,1)) -> 1 | P5: =VLOOKUP(M5,logika,2,FALSE) -> B | Q5: =VLOOKUP(N5,logika,2,FALSE) -> A | R5: =VLOOKUP(O5,logika,2,FALSE) -> B | S5: =CONCATENATE(P5,Q5,R5) -> BAB
B6: ='Data Supply'!H6 -> 3 | C6: ='Data Supply'!I6 -> Terusan Motif | D6: ='Data Supply'!J6 -> Nur3 | G6: =_xlfn.IFNA(VLOOKUP(E6,$L$4:$S$550,8,FALSE),"") | J6: 2 | K6: C | L6: =L5+1000 -> 102000 | M6: =VALUE(LEFT(L6,1)) -> 1 | N6: =VALUE(MID(L6,2,1)) -> 0 | O6: =VALUE(MID(L6,3,1)) -> 2 | P6: =VLOOKUP(M6,logika,2,FALSE) -> B | Q6: =VLOOKUP(N6,logika,2,FALSE) -> A | R6: =VLOOKUP(O6,logika,2,FALSE) -> C | S6: =CONCATENATE(P6,Q6,R6) -> BAC
B7: ='Data Supply'!H7 -> 4 | C7: ='Data Supply'!I7 -> Ms Style | D7: ='Data Supply'!J7 -> Nur4 | G7: =_xlfn.IFNA(VLOOKUP(E7,$L$4:$S$550,8,FALSE),"") | J7: 3 | K7: D | L7: =L6+1000 -> 103000 | M7: =VALUE(LEFT(L7,1)) -> 1 | N7: =VALUE(MID(L7,2,1)) -> 0 | O7: =VALUE(MID(L7,3,1)) -> 3 | P7: =VLOOKUP(M7,logika,2,FALSE) -> B | Q7: =VLOOKUP(N7,logika,2,FALSE) -> A | R7: =VLOOKUP(O7,logika,2,FALSE) -> D | S7: =CONCATENATE(P7,Q7,R7) -> BAD
B8: ='Data Supply'!H8 -> 5 | C8: ='Data Supply'!I8 -> Abb Motif | D8: ='Data Supply'!J8 -> Nur5 | G8: =_xlfn.IFNA(VLOOKUP(E8,$L$4:$S$550,8,FALSE),"") | J8: 4 | K8: E | L8: =L7+1000 -> 104000 | M8: =VALUE(LEFT(L8,1)) -> 1 | N8: =VALUE(MID(L8,2,1)) -> 0 | O8: =VALUE(MID(L8,3,1)) -> 4 | P8: =VLOOKUP(M8,logika,2,FALSE) -> B | Q8: =VLOOKUP(N8,logika,2,FALSE) -> A | R8: =VLOOKUP(O8,logika,2,FALSE) -> E | S8: =CONCATENATE(P8,Q8,R8) -> BAE
B9: ='Data Supply'!H9 -> 6 | C9: ='Data Supply'!I9 -> Abb Bordir | D9: ='Data Supply'!J9 -> Nur6 | G9: =_xlfn.IFNA(VLOOKUP(E9,$L$4:$S$550,8,FALSE),"") | J9: 5 | K9: F | L9: =L8+1000 -> 105000 | M9: =VALUE(LEFT(L9,1)) -> 1 | N9: =VALUE(MID(L9,2,1)) -> 0 | O9: =VALUE(MID(L9,3,1)) -> 5 | P9: =VLOOKUP(M9,logika,2,FALSE) -> B | Q9: =VLOOKUP(N9,logika,2,FALSE) -> A | R9: =VLOOKUP(O9,logika,2,FALSE) -> F | S9: =CONCATENATE(P9,Q9,R9) -> BAF
B10: ='Data Supply'!H10 -> 7 | C10: ='Data Supply'!I10 -> Abb Bordir 261 | D10: ='Data Supply'!J10 -> Nur7 | G10: =_xlfn.IFNA(VLOOKUP(E10,$L$4:$S$550,8,FALSE),"") | J10: 6 | K10: G | L10: =L9+1000 -> 106000 | M10: =VALUE(LEFT(L10,1)) -> 1 | N10: =VALUE(MID(L10,2,1)) -> 0 | O10: =VALUE(MID(L10,3,1)) -> 6 | P10: =VLOOKUP(M10,logika,2,FALSE) -> B | Q10: =VLOOKUP(N10,logika,2,FALSE) -> A | R10: =VLOOKUP(O10,logika,2,FALSE) -> G | S10: =CONCATENATE(P10,Q10,R10) -> BAG
B11: ='Data Supply'!H11 -> 8 | C11: ='Data Supply'!I11 -> Abh Motif | D11: ='Data Supply'!J11 -> Nur8 | G11: =_xlfn.IFNA(VLOOKUP(E11,$L$4:$S$550,8,FALSE),"") | J11: 7 | K11: H | L11: =L10+1000 -> 107000 | M11: =VALUE(LEFT(L11,1)) -> 1 | N11: =VALUE(MID(L11,2,1)) -> 0 | O11: =VALUE(MID(L11,3,1)) -> 7 | P11: =VLOOKUP(M11,logika,2,FALSE) -> B | Q11: =VLOOKUP(N11,logika,2,FALSE) -> A | R11: =VLOOKUP(O11,logika,2,FALSE) -> H | S11: =CONCATENATE(P11,Q11,R11) -> BAH
B12: ='Data Supply'!H12 -> 9 | C12: ='Data Supply'!I12 -> Anak XL | D12: ='Data Supply'!J12 -> Nur9 | G12: =_xlfn.IFNA(VLOOKUP(E12,$L$4:$S$550,8,FALSE),"") | J12: 8 | K12: I | L12: =L11+1000 -> 108000 | M12: =VALUE(LEFT(L12,1)) -> 1 | N12: =VALUE(MID(L12,2,1)) -> 0 | O12: =VALUE(MID(L12,3,1)) -> 8 | P12: =VLOOKUP(M12,logika,2,FALSE) -> B | Q12: =VLOOKUP(N12,logika,2,FALSE) -> A | R12: =VLOOKUP(O12,logika,2,FALSE) -> I | S12: =CONCATENATE(P12,Q12,R12) -> BAI
B13: ='Data Supply'!H13 -> 10 | C13: ='Data Supply'!I13 -> Anak L | D13: ='Data Supply'!J13 -> Nur10 | G13: =_xlfn.IFNA(VLOOKUP(E13,$L$4:$S$550,8,FALSE),"") | J13: 9 | K13: J | L13: =L12+1000 -> 109000 | M13: =VALUE(LEFT(L13,1)) -> 1 | N13: =VALUE(MID(L13,2,1)) -> 0 | O13: =VALUE(MID(L13,3,1)) -> 9 | P13: =VLOOKUP(M13,logika,2,FALSE) -> B | Q13: =VLOOKUP(N13,logika,2,FALSE) -> A | R13: =VLOOKUP(O13,logika,2,FALSE) -> J | S13: =CONCATENATE(P13,Q13,R13) -> BAJ
B14: ='Data Supply'!H14 -> 11 | C14: ='Data Supply'!I14 -> Anak M | D14: ='Data Supply'!J14 -> Nur11 | G14: =_xlfn.IFNA(VLOOKUP(E14,$L$4:$S$550,8,FALSE),"") | L14: =L13+1000 -> 110000 | M14: =VALUE(LEFT(L14,1)) -> 1 | N14: =VALUE(MID(L14,2,1)) -> 1 | O14: =VALUE(MID(L14,3,1)) -> 0 | P14: =VLOOKUP(M14,logika,2,FALSE) -> B | Q14: =VLOOKUP(N14,logika,2,FALSE) -> B | R14: =VLOOKUP(O14,logika,2,FALSE) -> A | S14: =CONCATENATE(P14,Q14,R14) -> BBA
B15: ='Data Supply'!H15 -> 12 | C15: ='Data Supply'!I15 -> Abh Anak M | D15: ='Data Supply'!J15 -> Nur12 | G15: =_xlfn.IFNA(VLOOKUP(E15,$L$4:$S$550,8,FALSE),"") | L15: =L14+1000 -> 111000 | M15: =VALUE(LEFT(L15,1)) -> 1 | N15: =VALUE(MID(L15,2,1)) -> 1 | O15: =VALUE(MID(L15,3,1)) -> 1 | P15: =VLOOKUP(M15,logika,2,FALSE) -> B | Q15: =VLOOKUP(N15,logika,2,FALSE) -> B | R15: =VLOOKUP(O15,logika,2,FALSE) -> B | S15: =CONCATENATE(P15,Q15,R15) -> BBB
B16: ='Data Supply'!H16 -> 13 | C16: ='Data Supply'!I16 -> Abh Anak L | D16: ='Data Supply'!J16 -> Nur13 | G16: =_xlfn.IFNA(VLOOKUP(E16,$L$4:$S$550,8,FALSE),"") | L16: =L15+1000 -> 112000 | M16: =VALUE(LEFT(L16,1)) -> 1 | N16: =VALUE(MID(L16,2,1)) -> 1 | O16: =VALUE(MID(L16,3,1)) -> 2 | P16: =VLOOKUP(M16,logika,2,FALSE) -> B | Q16: =VLOOKUP(N16,logika,2,FALSE) -> B | R16: =VLOOKUP(O16,logika,2,FALSE) -> C | S16: =CONCATENATE(P16,Q16,R16) -> BBC
B17: ='Data Supply'!H17 -> 14 | C17: ='Data Supply'!I17 -> Abh Motif | D17: ='Data Supply'!J17 -> Muk14 | G17: =_xlfn.IFNA(VLOOKUP(E17,$L$4:$S$550,8,FALSE),"") | L17: =L16+1000 -> 113000 | M17: =VALUE(LEFT(L17,1)) -> 1 | N17: =VALUE(MID(L17,2,1)) -> 1 | O17: =VALUE(MID(L17,3,1)) -> 3 | P17: =VLOOKUP(M17,logika,2,FALSE) -> B | Q17: =VLOOKUP(N17,logika,2,FALSE) -> B | R17: =VLOOKUP(O17,logika,2,FALSE) -> D | S17: =CONCATENATE(P17,Q17,R17) -> BBD
B18: ='Data Supply'!H18 -> 15 | C18: ='Data Supply'!I18 -> Terusan Motif | D18: ='Data Supply'!J18 -> Muk15 | G18: =_xlfn.IFNA(VLOOKUP(E18,$L$4:$S$550,8,FALSE),"") | L18: =L17+1000 -> 114000 | M18: =VALUE(LEFT(L18,1)) -> 1 | N18: =VALUE(MID(L18,2,1)) -> 1 | O18: =VALUE(MID(L18,3,1)) -> 4 | P18: =VLOOKUP(M18,logika,2,FALSE) -> B | Q18: =VLOOKUP(N18,logika,2,FALSE) -> B | R18: =VLOOKUP(O18,logika,2,FALSE) -> E | S18: =CONCATENATE(P18,Q18,R18) -> BBE
B19: ='Data Supply'!H19 -> 16 | C19: ='Data Supply'!I19 -> Abh Terompah | D19: ='Data Supply'!J19 -> Muk16 | G19: =_xlfn.IFNA(VLOOKUP(E19,$L$4:$S$550,8,FALSE),"") | L19: =L18+1000 -> 115000 | M19: =VALUE(LEFT(L19,1)) -> 1 | N19: =VALUE(MID(L19,2,1)) -> 1 | O19: =VALUE(MID(L19,3,1)) -> 5 | P19: =VLOOKUP(M19,logika,2,FALSE) -> B | Q19: =VLOOKUP(N19,logika,2,FALSE) -> B | R19: =VLOOKUP(O19,logika,2,FALSE) -> F | S19: =CONCATENATE(P19,Q19,R19) -> BBF
B20: ='Data Supply'!H20 -> 17 | C20: ='Data Supply'!I20 -> M006 | D20: ='Data Supply'!J20 -> Asy17 | G20: =_xlfn.IFNA(VLOOKUP(E20,$L$4:$S$550,8,FALSE),"") | L20: =L19+1000 -> 116000 | M20: =VALUE(LEFT(L20,1)) -> 1 | N20: =VALUE(MID(L20,2,1)) -> 1 | O20: =VALUE(MID(L20,3,1)) -> 6 | P20: =VLOOKUP(M20,logika,2,FALSE) -> B | Q20: =VLOOKUP(N20,logika,2,FALSE) -> B | R20: =VLOOKUP(O20,logika,2,FALSE) -> G | S20: =CONCATENATE(P20,Q20,R20) -> BBG
B21: ='Data Supply'!H21 -> 18 | C21: ='Data Supply'!I21 -> M005 | D21: ='Data Supply'!J21 -> Asy18 | G21: =_xlfn.IFNA(VLOOKUP(E21,$L$4:$S$550,8,FALSE),"") | L21: =L20+1000 -> 117000 | M21: =VALUE(LEFT(L21,1)) -> 1 | N21: =VALUE(MID(L21,2,1)) -> 1 | O21: =VALUE(MID(L21,3,1)) -> 7 | P21: =VLOOKUP(M21,logika,2,FALSE) -> B | Q21: =VLOOKUP(N21,logika,2,FALSE) -> B | R21: =VLOOKUP(O21,logika,2,FALSE) -> H | S21: =CONCATENATE(P21,Q21,R21) -> BBH
B22: ='Data Supply'!H22 -> 19 | C22: ='Data Supply'!I22 -> M002 | D22: ='Data Supply'!J22 -> Asy19 | G22: =_xlfn.IFNA(VLOOKUP(E22,$L$4:$S$550,8,FALSE),"") | L22: =L21+1000 -> 118000 | M22: =VALUE(LEFT(L22,1)) -> 1 | N22: =VALUE(MID(L22,2,1)) -> 1 | O22: =VALUE(MID(L22,3,1)) -> 8 | P22: =VLOOKUP(M22,logika,2,FALSE) -> B | Q22: =VLOOKUP(N22,logika,2,FALSE) -> B | R22: =VLOOKUP(O22,logika,2,FALSE) -> I | S22: =CONCATENATE(P22,Q22,R22) -> BBI
B23: ='Data Supply'!H23 -> 20 | C23: ='Data Supply'!I23 -> M001 | D23: ='Data Supply'!J23 -> Asy20 | G23: =_xlfn.IFNA(VLOOKUP(E23,$L$4:$S$550,8,FALSE),"") | L23: =L22+1000 -> 119000 | M23: =VALUE(LEFT(L23,1)) -> 1 | N23: =VALUE(MID(L23,2,1)) -> 1 | O23: =VALUE(MID(L23,3,1)) -> 9 | P23: =VLOOKUP(M23,logika,2,FALSE) -> B | Q23: =VLOOKUP(N23,logika,2,FALSE) -> B | R23: =VLOOKUP(O23,logika,2,FALSE) -> J | S23: =CONCATENATE(P23,Q23,R23) -> BBJ
B24: ='Data Supply'!H24 -> 21 | C24: ='Data Supply'!I24 -> M007 | D24: ='Data Supply'!J24 -> Asy21 | G24: =_xlfn.IFNA(VLOOKUP(E24,$L$4:$S$550,8,FALSE),"") | L24: =L23+1000 -> 120000 | M24: =VALUE(LEFT(L24,1)) -> 1 | N24: =VALUE(MID(L24,2,1)) -> 2 | O24: =VALUE(MID(L24,3,1)) -> 0 | P24: =VLOOKUP(M24,logika,2,FALSE) -> B | Q24: =VLOOKUP(N24,logika,2,FALSE) -> C | R24: =VLOOKUP(O24,logika,2,FALSE) -> A | S24: =CONCATENATE(P24,Q24,R24) -> BCA
B25: ='Data Supply'!H25 -> 22 | C25: ='Data Supply'!I25 -> M008 | D25: ='Data Supply'!J25 -> Asy22 | G25: =_xlfn.IFNA(VLOOKUP(E25,$L$4:$S$550,8,FALSE),"") | L25: =L24+1000 -> 121000 | M25: =VALUE(LEFT(L25,1)) -> 1 | N25: =VALUE(MID(L25,2,1)) -> 2 | O25: =VALUE(MID(L25,3,1)) -> 1 | P25: =VLOOKUP(M25,logika,2,FALSE) -> B | Q25: =VLOOKUP(N25,logika,2,FALSE) -> C | R25: =VLOOKUP(O25,logika,2,FALSE) -> B | S25: =CONCATENATE(P25,Q25,R25) -> BCB
... B63: ='Data Supply'!H63 -> 0 | C63: ='Data Supply'!I63 -> 0 | D63: ='Data Supply'!J63 | G63: =_xlfn.IFNA(VLOOKUP(E63,$L$4:$S$550,8,FALSE),"") | L63: =L62+1000 -> 159000 | M63: =VALUE(LEFT(L63,1)) -> 1 | N63: =VALUE(MID(L63,2,1)) -> 5 | O63: =VALUE(MID(L63,3,1)) -> 9 | P63: =VLOOKUP(M63,logika,2,FALSE) -> B | Q63: =VLOOKUP(N63,logika,2,FALSE) -> F | R63: =VLOOKUP(O63,logika,2,FALSE) -> J | S63: =CONCATENATE(P63,Q63,R63) -> BFJ
L64: =L63+1000 -> 160000 | M64: =VALUE(LEFT(L64,1)) -> 1 | N64: =VALUE(MID(L64,2,1)) -> 6 | O64: =VALUE(MID(L64,3,1)) -> 0 | P64: =VLOOKUP(M64,logika,2,FALSE) -> B | Q64: =VLOOKUP(N64,logika,2,FALSE) -> G | R64: =VLOOKUP(O64,logika,2,FALSE) -> A | S64: =CONCATENATE(P64,Q64,R64) -> BGA
L65: =L64+1000 -> 161000 | M65: =VALUE(LEFT(L65,1)) -> 1 | N65: =VALUE(MID(L65,2,1)) -> 6 | O65: =VALUE(MID(L65,3,1)) -> 1 | P65: =VLOOKUP(M65,logika,2,FALSE) -> B | Q65: =VLOOKUP(N65,logika,2,FALSE) -> G | R65: =VLOOKUP(O65,logika,2,FALSE) -> B | S65: =CONCATENATE(P65,Q65,R65) -> BGB
L66: =L65+1000 -> 162000 | M66: =VALUE(LEFT(L66,1)) -> 1 | N66: =VALUE(MID(L66,2,1)) -> 6 | O66: =VALUE(MID(L66,3,1)) -> 2 | P66: =VLOOKUP(M66,logika,2,FALSE) -> B | Q66: =VLOOKUP(N66,logika,2,FALSE) -> G | R66: =VLOOKUP(O66,logika,2,FALSE) -> C | S66: =CONCATENATE(P66,Q66,R66) -> BGC
L67: =L66+1000 -> 163000 | M67: =VALUE(LEFT(L67,1)) -> 1 | N67: =VALUE(MID(L67,2,1)) -> 6 | O67: =VALUE(MID(L67,3,1)) -> 3 | P67: =VLOOKUP(M67,logika,2,FALSE) -> B | Q67: =VLOOKUP(N67,logika,2,FALSE) -> G | R67: =VLOOKUP(O67,logika,2,FALSE) -> D | S67: =CONCATENATE(P67,Q67,R67) -> BGD
L68: =L67+1000 -> 164000 | M68: =VALUE(LEFT(L68,1)) -> 1 | N68: =VALUE(MID(L68,2,1)) -> 6 | O68: =VALUE(MID(L68,3,1)) -> 4 | P68: =VLOOKUP(M68,logika,2,FALSE) -> B | Q68: =VLOOKUP(N68,logika,2,FALSE) -> G | R68: =VLOOKUP(O68,logika,2,FALSE) -> E | S68: =CONCATENATE(P68,Q68,R68) -> BGE
L69: =L68+1000 -> 165000 | M69: =VALUE(LEFT(L69,1)) -> 1 | N69: =VALUE(MID(L69,2,1)) -> 6 | O69: =VALUE(MID(L69,3,1)) -> 5 | P69: =VLOOKUP(M69,logika,2,FALSE) -> B | Q69: =VLOOKUP(N69,logika,2,FALSE) -> G | R69: =VLOOKUP(O69,logika,2,FALSE) -> F | S69: =CONCATENATE(P69,Q69,R69) -> BGF
L70: =L69+1000 -> 166000 | M70: =VALUE(LEFT(L70,1)) -> 1 | N70: =VALUE(MID(L70,2,1)) -> 6 | O70: =VALUE(MID(L70,3,1)) -> 6 | P70: =VLOOKUP(M70,logika,2,FALSE) -> B | Q70: =VLOOKUP(N70,logika,2,FALSE) -> G | R70: =VLOOKUP(O70,logika,2,FALSE) -> G | S70: =CONCATENATE(P70,Q70,R70) -> BGG
L71: =L70+1000 -> 167000 | M71: =VALUE(LEFT(L71,1)) -> 1 | N71: =VALUE(MID(L71,2,1)) -> 6 | O71: =VALUE(MID(L71,3,1)) -> 7 | P71: =VLOOKUP(M71,logika,2,FALSE) -> B | Q71: =VLOOKUP(N71,logika,2,FALSE) -> G | R71: =VLOOKUP(O71,logika,2,FALSE) -> H | S71: =CONCATENATE(P71,Q71,R71) -> BGH
L72: =L71+1000 -> 168000 | M72: =VALUE(LEFT(L72,1)) -> 1 | N72: =VALUE(MID(L72,2,1)) -> 6 | O72: =VALUE(MID(L72,3,1)) -> 8 | P72: =VLOOKUP(M72,logika,2,FALSE) -> B | Q72: =VLOOKUP(N72,logika,2,FALSE) -> G | R72: =VLOOKUP(O72,logika,2,FALSE) -> I | S72: =CONCATENATE(P72,Q72,R72) -> BGI
L73: =L72+1000 -> 169000 | M73: =VALUE(LEFT(L73,1)) -> 1 | N73: =VALUE(MID(L73,2,1)) -> 6 | O73: =VALUE(MID(L73,3,1)) -> 9 | P73: =VLOOKUP(M73,logika,2,FALSE) -> B | Q73: =VLOOKUP(N73,logika,2,FALSE) -> G | R73: =VLOOKUP(O73,logika,2,FALSE) -> J | S73: =CONCATENATE(P73,Q73,R73) -> BGJ
L74: =L73+1000 -> 170000 | M74: =VALUE(LEFT(L74,1)) -> 1 | N74: =VALUE(MID(L74,2,1)) -> 7 | O74: =VALUE(MID(L74,3,1)) -> 0 | P74: =VLOOKUP(M74,logika,2,FALSE) -> B | Q74: =VLOOKUP(N74,logika,2,FALSE) -> H | R74: =VLOOKUP(O74,logika,2,FALSE) -> A | S74: =CONCATENATE(P74,Q74,R74) -> BHA
L75: =L74+1000 -> 171000 | M75: =VALUE(LEFT(L75,1)) -> 1 | N75: =VALUE(MID(L75,2,1)) -> 7 | O75: =VALUE(MID(L75,3,1)) -> 1 | P75: =VLOOKUP(M75,logika,2,FALSE) -> B | Q75: =VLOOKUP(N75,logika,2,FALSE) -> H | R75: =VLOOKUP(O75,logika,2,FALSE) -> B | S75: =CONCATENATE(P75,Q75,R75) -> BHB
... L550: =L549+1000 -> 646000 | M550: =VALUE(LEFT(L550,1)) -> 6 | N550: =VALUE(MID(L550,2,1)) -> 4 | O550: =VALUE(MID(L550,3,1)) -> 6 | P550: =VLOOKUP(M550,logika,2,FALSE) -> G | Q550: =VLOOKUP(N550,logika,2,FALSE) -> E | R550: =VLOOKUP(O550,logika,2,FALSE) -> G | S550: =CONCATENATE(P550,Q550,R550) -> GEG

Sheet Laporan
B2: Laporan Transaksi | I2: Laporan Stok Barang | K2: =TODAY() -> 44638
B3: Hari,Tanggal Transaksi | C3: No | D3: Nama Barang | E3: Kode | F3: Jumlah | G3: Total Harga | I3: No | J3: Nama Barang | K3: Stok Dijual | L3: Stok Sisa
B4: ='Input Penjualan'!B4 -> 44638 | C4: =IF(B4="","",ROW()-3) -> 1 | D4: =IF('Input Penjualan'!D4="","",'Input Penjualan'!D4) -> 10466 | E4: ='Input Penjualan'!E4 -> Asy33 | F4: =IF('Input Penjualan'!F4="","",'Input Penjualan'!F4) -> 1 | G4: =IF('Input Penjualan'!H4="","",'Input Penjualan'!H4) -> 205000 | I4: ='Input Penjualan'!M4 -> 1 | J4: ='Input Penjualan'!N4 -> Terusan Bordir | K4: =IF('Input Penjualan'!P4=0,"-",'Input Penjualan'!P4) -> - | L4: =IF('Input Penjualan'!Q4=0,"-",'Input Penjualan'!Q4) -> 9
B5: ='Input Penjualan'!B5 -> 44638 | C5: =IF(B5="","",ROW()-3) -> 2 | D5: =IF('Input Penjualan'!D5="","",'Input Penjualan'!D5) -> Bordir Alisha | E5: ='Input Penjualan'!E5 -> Nur2 | F5: =IF('Input Penjualan'!F5="","",'Input Penjualan'!F5) -> 3 | G5: =IF('Input Penjualan'!H5="","",'Input Penjualan'!H5) -> 190000 | I5: ='Input Penjualan'!M5 -> 2 | J5: ='Input Penjualan'!N5 -> Bordir Alisha | K5: =IF('Input Penjualan'!P5=0,"-",'Input Penjualan'!P5) -> 3 | L5: =IF('Input Penjualan'!Q5=0,"-",'Input Penjualan'!Q5) -> -
B6: ='Input Penjualan'!B6 -> 44638 | C6: =IF(B6="","",ROW()-3) -> 3 | D6: =IF('Input Penjualan'!D6="","",'Input Penjualan'!D6) -> Abb Motif | E6: ='Input Penjualan'!E6 -> Nur5 | F6: =IF('Input Penjualan'!F6="","",'Input Penjualan'!F6) | G6: =IF('Input Penjualan'!H6="","",'Input Penjualan'!H6) | I6: ='Input Penjualan'!M6 -> 3 | J6: ='Input Penjualan'!N6 -> Terusan Motif | K6: =IF('Input Penjualan'!P6=0,"-",'Input Penjualan'!P6) -> - | L6: =IF('Input Penjualan'!Q6=0,"-",'Input Penjualan'!Q6) -> 23
B7: ='Input Penjualan'!B7 | C7: =IF(B7="","",ROW()-3) | D7: =IF('Input Penjualan'!D7="","",'Input Penjualan'!D7) | E7: ='Input Penjualan'!E7 | F7: =IF('Input Penjualan'!F7="","",'Input Penjualan'!F7) | G7: =IF('Input Penjualan'!H7="","",'Input Penjualan'!H7) | I7: ='Input Penjualan'!M7 -> 4 | J7: ='Input Penjualan'!N7 -> Ms Style | K7: =IF('Input Penjualan'!P7=0,"-",'Input Penjualan'!P7) -> - | L7: =IF('Input Penjualan'!Q7=0,"-",'Input Penjualan'!Q7) -> 5
B8: ='Input Penjualan'!B8 | C8: =IF(B8="","",ROW()-3) | D8: =IF('Input Penjualan'!D8="","",'Input Penjualan'!D8) | E8: ='Input Penjualan'!E8 | F8: =IF('Input Penjualan'!F8="","",'Input Penjualan'!F8) | G8: =IF('Input Penjualan'!H8="","",'Input Penjualan'!H8) | I8: ='Input Penjualan'!M8 -> 5 | J8: ='Input Penjualan'!N8 -> Abb Motif | K8: =IF('Input Penjualan'!P8=0,"-",'Input Penjualan'!P8) -> - | L8: =IF('Input Penjualan'!Q8=0,"-",'Input Penjualan'!Q8) -> 12
B9: ='Input Penjualan'!B9 | C9: =IF(B9="","",ROW()-3) | D9: =IF('Input Penjualan'!D9="","",'Input Penjualan'!D9) | E9: ='Input Penjualan'!E9 | F9: =IF('Input Penjualan'!F9="","",'Input Penjualan'!F9) | G9: =IF('Input Penjualan'!H9="","",'Input Penjualan'!H9) | I9: ='Input Penjualan'!M9 -> 6 | J9: ='Input Penjualan'!N9 -> Abb Bordir | K9: =IF('Input Penjualan'!P9=0,"-",'Input Penjualan'!P9) -> - | L9: =IF('Input Penjualan'!Q9=0,"-",'Input Penjualan'!Q9) -> 2
B10: ='Input Penjualan'!B10 | C10: =IF(B10="","",ROW()-3) | D10: =IF('Input Penjualan'!D10="","",'Input Penjualan'!D10) | E10: ='Input Penjualan'!E10 | F10: =IF('Input Penjualan'!F10="","",'Input Penjualan'!F10) | G10: =IF('Input Penjualan'!H10="","",'Input Penjualan'!H10) | I10: ='Input Penjualan'!M10 -> 7 | J10: ='Input Penjualan'!N10 -> Abb Bordir 261 | K10: =IF('Input Penjualan'!P10=0,"-",'Input Penjualan'!P10) -> - | L10: =IF('Input Penjualan'!Q10=0,"-",'Input Penjualan'!Q10) -> 2
B11: ='Input Penjualan'!B11 | C11: =IF(B11="","",ROW()-3) | D11: =IF('Input Penjualan'!D11="","",'Input Penjualan'!D11) | E11: ='Input Penjualan'!E11 | F11: =IF('Input Penjualan'!F11="","",'Input Penjualan'!F11) | G11: =IF('Input Penjualan'!H11="","",'Input Penjualan'!H11) | I11: ='Input Penjualan'!M11 -> 8 | J11: ='Input Penjualan'!N11 -> Abh Motif | K11: =IF('Input Penjualan'!P11=0,"-",'Input Penjualan'!P11) -> - | L11: =IF('Input Penjualan'!Q11=0,"-",'Input Penjualan'!Q11) -> 13
B12: ='Input Penjualan'!B12 | C12: =IF(B12="","",ROW()-3) | D12: =IF('Input Penjualan'!D12="","",'Input Penjualan'!D12) | E12: ='Input Penjualan'!E12 | F12: =IF('Input Penjualan'!F12="","",'Input Penjualan'!F12) | G12: =IF('Input Penjualan'!H12="","",'Input Penjualan'!H12) | I12: ='Input Penjualan'!M12 -> 9 | J12: ='Input Penjualan'!N12 -> Anak XL | K12: =IF('Input Penjualan'!P12=0,"-",'Input Penjualan'!P12) -> - | L12: =IF('Input Penjualan'!Q12=0,"-",'Input Penjualan'!Q12) -> 7
B13: ='Input Penjualan'!B13 | C13: =IF(B13="","",ROW()-3) | D13: =IF('Input Penjualan'!D13="","",'Input Penjualan'!D13) | E13: ='Input Penjualan'!E13 | F13: =IF('Input Penjualan'!F13="","",'Input Penjualan'!F13) | G13: =IF('Input Penjualan'!H13="","",'Input Penjualan'!H13) | I13: ='Input Penjualan'!M13 -> 10 | J13: ='Input Penjualan'!N13 -> Anak L | K13: =IF('Input Penjualan'!P13=0,"-",'Input Penjualan'!P13) -> - | L13: =IF('Input Penjualan'!Q13=0,"-",'Input Penjualan'!Q13) -> 1
B14: ='Input Penjualan'!B14 | C14: =IF(B14="","",ROW()-3) | D14: =IF('Input Penjualan'!D14="","",'Input Penjualan'!D14) | E14: ='Input Penjualan'!E14 | F14: =IF('Input Penjualan'!F14="","",'Input Penjualan'!F14) | G14: =IF('Input Penjualan'!H14="","",'Input Penjualan'!H14) | I14: ='Input Penjualan'!M14 -> 11 | J14: ='Input Penjualan'!N14 -> Anak M | K14: =IF('Input Penjualan'!P14=0,"-",'Input Penjualan'!P14) -> - | L14: =IF('Input Penjualan'!Q14=0,"-",'Input Penjualan'!Q14) -> 6
B15: ='Input Penjualan'!B15 | C15: =IF(B15="","",ROW()-3) | D15: =IF('Input Penjualan'!D15="","",'Input Penjualan'!D15) | E15: ='Input Penjualan'!E15 | F15: =IF('Input Penjualan'!F15="","",'Input Penjualan'!F15) | G15: =IF('Input Penjualan'!H15="","",'Input Penjualan'!H15) | I15: ='Input Penjualan'!M15 -> 12 | J15: ='Input Penjualan'!N15 -> Abh Anak M | K15: =IF('Input Penjualan'!P15=0,"-",'Input Penjualan'!P15) -> - | L15: =IF('Input Penjualan'!Q15=0,"-",'Input Penjualan'!Q15) -> 2
... B60: ='Input Penjualan'!B60 -> 0 | C60: =IF(B60="","",ROW()-3) -> 57 | D60: =IF('Input Penjualan'!D60="","",'Input Penjualan'!D60) | E60: ='Input Penjualan'!E60 -> 0 | F60: =IF('Input Penjualan'!F60="","",'Input Penjualan'!F60) | G60: =IF('Input Penjualan'!H60="","",'Input Penjualan'!H60) | I60: ='Input Penjualan'!M60 -> 0 | J60: ='Input Penjualan'!N60 -> 0 | K60: =IF('Input Penjualan'!P60=0,"-",'Input Penjualan'!P60) -> - | L60: =IF('Input Penjualan'!Q60=0,"-",'Input Penjualan'!Q60) -> -
I61: ='Input Penjualan'!M61 -> 0 | J61: ='Input Penjualan'!N61 -> 0 | K61: =IF('Input Penjualan'!P61=0,"-",'Input Penjualan'!P61) -> - | L61: =IF('Input Penjualan'!Q61=0,"-",'Input Penjualan'!Q61) -> -
